#VRML_SIM R2021b utf8
WorldInfo {
  coordinateSystem "NUE"
}
Viewpoint {
  orientation 0.003382157800320229 -0.9989689216654903 -0.045273110729227586 3.1086802833711467
  position 0.6142542200418608 0.02221074429272081 0.5532352821339122
  follow "robot:distance_sensor"
}
TexturedBackground {
}
TexturedBackgroundLight {
}
DEF GROUND Group {
  children [
    Solid {
      translation 2.1 0 0
      children [
        Shape {
          appearance Appearance {
            texture ImageTexture {
              url [
                "../tiles/RT.png"
              ]
            }
          }
          geometry Plane {
            size 0.3 0.3
          }
        }
      ]
      name "solid7"
    }
    Solid {
      translation 2.1 0 0.3
      children [
        Shape {
          appearance Appearance {
            texture ImageTexture {
              url [
                "../tiles/2R.png"
              ]
            }
          }
          geometry Plane {
            size 0.3 0.3
          }
        }
      ]
      name "solid72"
    }
    Solid {
      translation 2.1 0 0.6
      children [
        Shape {
          appearance Appearance {
            texture ImageTexture {
              url [
                "../tiles/2R.png"
              ]
            }
          }
          geometry Plane {
            size 0.3 0.3
          }
        }
      ]
      name "solid73"
    }
    Solid {
      translation 2.1 0 0.9
      children [
        Shape {
          appearance Appearance {
            texture ImageTexture {
              url [
                "../tiles/2R.png"
              ]
            }
          }
          geometry Plane {
            size 0.3 0.3
          }
        }
      ]
      name "solid74"
    }
    Solid {
      translation 2.1 0 1.2
      children [
        Shape {
          appearance Appearance {
            texture ImageTexture {
              url [
                "../tiles/2R.png"
              ]
            }
          }
          geometry Plane {
            size 0.3 0.3
          }
        }
      ]
      name "solid75"
    }
    Solid {
      translation 2.1 0 1.5
      children [
        Shape {
          appearance Appearance {
            texture ImageTexture {
              url [
                "../tiles/2R.png"
              ]
            }
          }
          geometry Plane {
            size 0.3 0.3
          }
        }
      ]
      name "solid76"
    }
    Solid {
      translation 2.1 0 1.8
      children [
        Shape {
          appearance Appearance {
            texture ImageTexture {
              url [
                "../tiles/RB.png"
              ]
            }
          }
          geometry Plane {
            size 0.3 0.3
          }
        }
      ]
      name "solid77"
    }
    Solid {
      translation 1.8 0 0
      children [
        Shape {
          appearance Appearance {
            texture ImageTexture {
              url [
                "../tiles/1T.png"
              ]
            }
          }
          geometry Plane {
            size 0.3 0.3
          }
        }
      ]
      name "solid6"
    }
    Solid {
      translation 1.8 0 0.3
      children [
        Shape {
          appearance Appearance {
            texture ImageTexture {
              url [
                "../tiles/0.png"
              ]
            }
          }
          geometry Plane {
            size 0.3 0.3
          }
        }
      ]
      name "solid62"
    }
    Solid {
      translation 1.8 0 0.6
      children [
        Shape {
          appearance Appearance {
            texture ImageTexture {
              url [
                "../tiles/0.png"
              ]
            }
          }
          geometry Plane {
            size 0.3 0.3
          }
        }
      ]
      name "solid63"
    }
    Solid {
      translation 1.8 0 0.9
      children [
        Shape {
          appearance Appearance {
            texture ImageTexture {
              url [
                "../tiles/0.png"
              ]
            }
          }
          geometry Plane {
            size 0.3 0.3
          }
        }
      ]
      name "solid64"
    }
    Solid {
      translation 1.8 0 1.2
      children [
        Shape {
          appearance Appearance {
            texture ImageTexture {
              url [
                "../tiles/0.png"
              ]
            }
          }
          geometry Plane {
            size 0.3 0.3
          }
        }
      ]
      name "solid65"
    }
    Solid {
      translation 1.8 0 1.5
      children [
        Shape {
          appearance Appearance {
            texture ImageTexture {
              url [
                "../tiles/0.png"
              ]
            }
          }
          geometry Plane {
            size 0.3 0.3
          }
        }
      ]
      name "solid66"
    }
    Solid {
      translation 1.8 0 1.8
      children [
        Shape {
          appearance Appearance {
            texture ImageTexture {
              url [
                "../tiles/1B.png"
              ]
            }
          }
          geometry Plane {
            size 0.3 0.3
          }
        }
      ]
      name "solid67"
    }
    Solid {
      translation 1.5 0 0
      children [
        Shape {
          appearance Appearance {
            texture ImageTexture {
              url [
                "../tiles/1T.png"
              ]
            }
          }
          geometry Plane {
            size 0.3 0.3
          }
        }
      ]
      name "solid5"
    }
    Solid {
      translation 1.5 0 0.3
      children [
        Shape {
          appearance Appearance {
            texture ImageTexture {
              url [
                "../tiles/0.png"
              ]
            }
          }
          geometry Plane {
            size 0.3 0.3
          }
        }
      ]
      name "solid52"
    }
    Solid {
      translation 1.5 0 0.6
      children [
        Shape {
          appearance Appearance {
            texture ImageTexture {
              url [
                "../tiles/0.png"
              ]
            }
          }
          geometry Plane {
            size 0.3 0.3
          }
        }
      ]
      name "solid53"
    }
    Solid {
      translation 1.5 0 0.9
      children [
        Shape {
          appearance Appearance {
            texture ImageTexture {
              url [
                "../tiles/0.png"
              ]
            }
          }
          geometry Plane {
            size 0.3 0.3
          }
        }
      ]
      name "solid54"
    }
    Solid {
      translation 1.5 0 1.2
      children [
        Shape {
          appearance Appearance {
            texture ImageTexture {
              url [
                "../tiles/0.png"
              ]
            }
          }
          geometry Plane {
            size 0.3 0.3
          }
        }
      ]
      name "solid55"
    }
    Solid {
      translation 1.5 0 1.5
      children [
        Shape {
          appearance Appearance {
            texture ImageTexture {
              url [
                "../tiles/0.png"
              ]
            }
          }
          geometry Plane {
            size 0.3 0.3
          }
        }
      ]
      name "solid56"
    }
    Solid {
      translation 1.5 0 1.8
      children [
        Shape {
          appearance Appearance {
            texture ImageTexture {
              url [
                "../tiles/1B.png"
              ]
            }
          }
          geometry Plane {
            size 0.3 0.3
          }
        }
      ]
      name "solid57"
    }
    Solid {
      translation 1.2 0 0
      children [
        Shape {
          appearance Appearance {
            texture ImageTexture {
              url [
                "../tiles/1T.png"
              ]
            }
          }
          geometry Plane {
            size 0.3 0.3
          }
        }
      ]
      name "solid4"
    }
    Solid {
      translation 1.2 0 0.3
      children [
        Shape {
          appearance Appearance {
            texture ImageTexture {
              url [
                "../tiles/0.png"
              ]
            }
          }
          geometry Plane {
            size 0.3 0.3
          }
        }
      ]
      name "solid42"
    }
    Solid {
      translation 1.2 0 0.6
      children [
        Shape {
          appearance Appearance {
            texture ImageTexture {
              url [
                "../tiles/0.png"
              ]
            }
          }
          geometry Plane {
            size 0.3 0.3
          }
        }
      ]
      name "solid43"
    }
    Solid {
      translation 1.2 0 0.9
      children [
        Shape {
          appearance Appearance {
            texture ImageTexture {
              url [
                "../tiles/20.png"
              ]
            }
          }
          geometry Plane {
            size 0.3 0.3
          }
        }
      ]
      name "solid44"
    }
    Solid {
      translation 1.2 0 1.2
      children [
        Shape {
          appearance Appearance {
            texture ImageTexture {
              url [
                "../tiles/0.png"
              ]
            }
          }
          geometry Plane {
            size 0.3 0.3
          }
        }
      ]
      name "solid45"
    }
    Solid {
      translation 1.2 0 1.5
      children [
        Shape {
          appearance Appearance {
            texture ImageTexture {
              url [
                "../tiles/0.png"
              ]
            }
          }
          geometry Plane {
            size 0.3 0.3
          }
        }
      ]
      name "solid46"
    }
    Solid {
      translation 1.2 0 1.8
      children [
        Shape {
          appearance Appearance {
            texture ImageTexture {
              url [
                "../tiles/1B.png"
              ]
            }
          }
          geometry Plane {
            size 0.3 0.3
          }
        }
      ]
      name "solid47"
    }
    Solid {
      translation 0.9 0 0
      children [
        Shape {
          appearance Appearance {
            texture ImageTexture {
              url [
                "../tiles/1T.png"
              ]
            }
          }
          geometry Plane {
            size 0.3 0.3
          }
        }
      ]
      name "solid3"
    }
    Solid {
      translation 0.9 0 0.3
      children [
        Shape {
          appearance Appearance {
            texture ImageTexture {
              url [
                "../tiles/0.png"
              ]
            }
          }
          geometry Plane {
            size 0.3 0.3
          }
        }
      ]
      name "solid32"
    }
    Solid {
      translation 0.9 0 0.6
      children [
        Shape {
          appearance Appearance {
            texture ImageTexture {
              url [
                "../tiles/0.png"
              ]
            }
          }
          geometry Plane {
            size 0.3 0.3
          }
        }
      ]
      name "solid33"
    }
    Solid {
      translation 0.9 0 0.9
      children [
        Shape {
          appearance Appearance {
            texture ImageTexture {
              url [
                "../tiles/0.png"
              ]
            }
          }
          geometry Plane {
            size 0.3 0.3
          }
        }
      ]
      name "solid34"
    }
    Solid {
      translation 0.9 0 1.2
      children [
        Shape {
          appearance Appearance {
            texture ImageTexture {
              url [
                "../tiles/0.png"
              ]
            }
          }
          geometry Plane {
            size 0.3 0.3
          }
        }
      ]
      name "solid35"
    }
    Solid {
      translation 0.9 0 1.5
      children [
        Shape {
          appearance Appearance {
            texture ImageTexture {
              url [
                "../tiles/0.png"
              ]
            }
          }
          geometry Plane {
            size 0.3 0.3
          }
        }
      ]
      name "solid36"
    }
    Solid {
      translation 0.9 0 1.8
      children [
        Shape {
          appearance Appearance {
            texture ImageTexture {
              url [
                "../tiles/1B.png"
              ]
            }
          }
          geometry Plane {
            size 0.3 0.3
          }
        }
      ]
      name "solid37"
    }
    Solid {
      translation 0.3 0 0
      children [
        Shape {
          appearance Appearance {
            texture ImageTexture {
              url [
                "../tiles/LT.png"
              ]
            }
          }
          geometry Plane {
            size 0.3 0.3
          }
        }
      ]
      name "solid1"
    }
    Solid {
      translation 0.3 0 0.3
      children [
        Shape {
          appearance Appearance {
            texture ImageTexture {
              url [
                "../tiles/2L.png"
              ]
            }
          }
          geometry Plane {
            size 0.3 0.3
          }
        }
      ]
      name "solid12"
    }
    Solid {
      translation 0.3 0 0.6
      children [
        Shape {
          appearance Appearance {
            texture ImageTexture {
              url [
                "../tiles/2L.png"
              ]
            }
          }
          geometry Plane {
            size 0.3 0.3
          }
        }
      ]
      name "solid13"
    }
    Solid {
      translation 0.3 0 0.9
      children [
        Shape {
          appearance Appearance {
            texture ImageTexture {
              url [
                "../tiles/2L.png"
              ]
            }
          }
          geometry Plane {
            size 0.3 0.3
          }
        }
      ]
      name "solid14"
    }
    Solid {
      translation 0.3 0 1.2
      children [
        Shape {
          appearance Appearance {
            texture ImageTexture {
              url [
                "../tiles/2L.png"
              ]
            }
          }
          geometry Plane {
            size 0.3 0.3
          }
        }
      ]
      name "solid15"
    }
    Solid {
      translation 0.3 0 1.5
      children [
        Shape {
          appearance Appearance {
            texture ImageTexture {
              url [
                "../tiles/2L.png"
              ]
            }
          }
          geometry Plane {
            size 0.3 0.3
          }
        }
      ]
      name "solid16"
    }
    Solid {
      translation 0.3 0 1.8
      children [
        Shape {
          appearance Appearance {
            texture ImageTexture {
              url [
                "../tiles/LB.png"
              ]
            }
          }
          geometry Plane {
            size 0.3 0.3
          }
        }
      ]
      name "solid17"
    }
    Solid {
      translation 0.6 0 0
      children [
        Shape {
          appearance Appearance {
            texture ImageTexture {
              url [
                "../tiles/1T.png"
              ]
            }
          }
          geometry Plane {
            size 0.3 0.3
          }
        }
      ]
      name "solid2"
    }
    Solid {
      translation 0.6 0 0.3
      children [
        Shape {
          appearance Appearance {
            texture ImageTexture {
              url [
                "../tiles/0.png"
              ]
            }
          }
          geometry Plane {
            size 0.3 0.3
          }
        }
      ]
      name "solid22"
    }
    Solid {
      translation 0.6 0 0.6
      children [
        Shape {
          appearance Appearance {
            texture ImageTexture {
              url [
                "../tiles/0.png"
              ]
            }
          }
          geometry Plane {
            size 0.3 0.3
          }
        }
      ]
      name "solid23"
    }
    Solid {
      translation 0.6 0 0.9
      children [
        Shape {
          appearance Appearance {
            texture ImageTexture {
              url [
                "../tiles/10.png"
              ]
            }
          }
          geometry Plane {
            size 0.3 0.3
          }
        }
      ]
      name "solid24"
    }
    Solid {
      translation 0.6 0 1.2
      children [
        Shape {
          appearance Appearance {
            texture ImageTexture {
              url [
                "../tiles/0.png"
              ]
            }
          }
          geometry Plane {
            size 0.3 0.3
          }
        }
      ]
      name "solid25"
    }
    Solid {
      translation 0.6 0 1.5
      children [
        Shape {
          appearance Appearance {
            texture ImageTexture {
              url [
                "../tiles/0.png"
              ]
            }
          }
          geometry Plane {
            size 0.3 0.3
          }
        }
      ]
      name "solid26"
    }
    Solid {
      translation 0.6 0 1.8
      children [
        Shape {
          appearance Appearance {
            texture ImageTexture {
              url [
                "../tiles/1B.png"
              ]
            }
          }
          geometry Plane {
            size 0.3 0.3
          }
        }
      ]
      name "solid27"
    }
    Solid {
      translation 1.25 -0.049 1
      boundingObject Box {
        size 2.5 0.1 2.5
      }
    }
  ]
}
DEF LIGHTSOURCE Group {
  children [
    PointLight {
      attenuation 0 0 1
      color 0 0 1
      intensity 0.25
      location 1.1 0.25 0.9
    }
  ]
}
DEF WALLS Group {
  children [
    Wall {
      translation 1.2 0 0.75
      name "wall1"
      size 0.3 0.5 0.05
    }
    Wall {
      translation 1.2 0 1.05
      name "wall2"
      size 0.3 0.5 0.05
    }
    Wall {
      translation 1.05 0 0.9
      name "wall3"
      size 0.05 0.5 0.3
    }
    Wall {
      translation 0.75 0 0
      name "wall4"
      size 0.05 0.5 0.3
    }
    Wall {
      translation 1.65 0 1.8
      name "wall7"
      size 0.05 0.5 0.3
    }
    Wall {
      translation 1.65 0 0
      name "wall6"
      size 0.05 0.5 0.3
    }
    Wall {
      translation 0.75 0 1.8
      name "wall5"
      size 0.05 0.5 0.3
    }
    Wall {
      translation 1.65 0 0.6
      name "wall8"
      size 0.05 0.5 0.3
    }
    Wall {
      translation 1.65 0 1.2
      name "wall9"
      size 0.05 0.5 0.3
    }
    Wall {
      translation 2.1 0 0.75
      name "wall10"
      size 0.3 0.5 0.05
    }
    Wall {
      translation 1.8 0 1.05
      name "wall11"
      size 0.3 0.5 0.05
    }
    Wall {
      translation 1.5 0 0.75
      name "wall12"
      size 0.3 0.5 0.05
    }
    Wall {
      translation 1.05 0 1.2
      name "wall13"
      size 0.05 0.5 0.3
    }
    Wall {
      translation 1.5 0 1.35
      name "wall14"
      size 0.3 0.5 0.05
    }
    Wall {
      translation 0.9 0 0.45
      name "wall15"
      size 0.3 0.5 0.05
    }
    Wall {
      translation 0.9 0 0.15
      name "wall16"
      size 0.3 0.5 0.05
    }
    Wall {
      translation 1.2 0 0.15
      name "wall17"
      size 0.3 0.5 0.05
    }
    Wall {
      translation 0.3 0 0.45
      name "wall18"
      size 0.3 0.5 0.05
    }
    Wall {
      translation 0.3 0 1.35
      name "wall19"
      size 0.3 0.5 0.05
    }
    Wall {
      translation 0.6 0 1.35
      name "wall20"
      size 0.3 0.5 0.05
    }
  ]
}
Robot {
  translation 0.6089958892306669 0.040472742033543466 0.9000006427870811
  rotation -3.1503791456690914e-08 0.9999999999999992 2.52671621914513e-08 1.5706500144546613
  children [
    DistanceSensor {
      translation 0 -0.03 0.055
      rotation 0 0 1 -1.5707953071795862
      children [
        Shape {
          appearance PBRAppearance {
          }
          geometry Box {
            size 0.01 0.01 0.01
          }
        }
      ]
      name "line_sensor"
      physics Physics {
      }
      type "infra-red"
    }
    LightSensor {
      translation 0 -0.025 0.05
      rotation 0 0 1 -1.5707996938995747
      children [
        Shape {
          appearance PBRAppearance {
          }
          geometry Box {
            size 0.01 0.02 0.01
          }
        }
      ]
      name "line_detector_sensor"
      colorFilter 0 0 0
    }
    LightSensor {
      translation 0 0.02 0.05
      rotation 0 1 0 -1.59
      children [
        Shape {
          appearance PBRAppearance {
          }
          geometry Box {
            size 0.01 0.01 0.01
          }
        }
      ]
      name "light_sensor"
    }
    HingeJoint {
      jointParameters HingeJointParameters {
        position 66.59995597191615
        anchor -0.02 -0.02 0.03
      }
      device [
        RotationalMotor {
          name "FRWHEEL"
        }
      ]
      endPoint Solid {
        translation -0.049998032662356695 -0.019994259132282692 0.02999596625538234
        rotation 0.6426410491291974 -0.6551027468688867 0.39730702613843094 2.3983145945741273
        children [
          Shape {
            appearance PBRAppearance {
            }
            geometry Cylinder {
              height 0.02
              radius 0.02
            }
          }
        ]
        boundingObject Cylinder {
          height 0.02
          radius 0.02
        }
        physics Physics {
        }
      }
    }
    HingeJoint {
      jointParameters HingeJointParameters {
        position 80.59996866892031
        anchor -0.02 -0.02 -0.03
      }
      device [
        RotationalMotor {
          name "BRWHEEL"
        }
      ]
      endPoint Solid {
        translation -0.0500019662295896 -0.019994257909138963 -0.029998567813509947
        rotation -0.6460366513734692 0.6585642835174594 0.3859141479102444 2.4177924246323075
        children [
          Shape {
            appearance PBRAppearance {
            }
            geometry Cylinder {
              height 0.02
              radius 0.02
            }
          }
        ]
        name "solid(2)"
        boundingObject Cylinder {
          height 0.02
          radius 0.02
        }
        physics Physics {
        }
      }
    }
    HingeJoint {
      jointParameters HingeJointParameters {
        position 74.5999754768884
        anchor 0.015 -0.02 -0.03
      }
      device [
        RotationalMotor {
          name "BLWHEEL"
        }
      ]
      endPoint Solid {
        translation 0.04999803155052675 -0.019994276954608092 -0.030000851479656167
        rotation -0.3562272104717419 0.3631349731901137 0.8609501528925682 1.7389215861265634
        children [
          Shape {
            appearance PBRAppearance {
            }
            geometry Cylinder {
              height 0.02
              radius 0.02
            }
          }
        ]
        name "solid(3)"
        boundingObject Cylinder {
          height 0.02
          radius 0.02
        }
        physics Physics {
        }
      }
    }
    HingeJoint {
      jointParameters HingeJointParameters {
        position 65.59996554128612
        anchor 0.015 -0.02 0.03
      }
      device [
        RotationalMotor {
          name "FLWHEEL"
        }
      ]
      endPoint Solid {
        translation 0.050001967309543614 -0.019994303170734213 0.030003467881661396
        rotation 0.1611442344237621 -0.16426897220893807 0.9731640357521432 1.6171865628175979
        children [
          Shape {
            appearance PBRAppearance {
            }
            geometry Cylinder {
              height 0.02
              radius 0.02
            }
          }
        ]
        name "solid(1)"
        boundingObject Cylinder {
          height 0.02
          radius 0.02
        }
        physics Physics {
        }
      }
    }
    DistanceSensor {
      translation 6.99334e-05 0.00982561 0.0493899
      rotation 0.01112216575729272 -0.9999129210601427 -0.007102656252445453 1.5776432937483473
      children [
        Shape {
          appearance PBRAppearance {
          }
          geometry Box {
            size 0.01 0.01 0.02
          }
        }
      ]
      name "distance_sensor"
      physics Physics {
      }
    }
    DEF Body Shape {
      appearance PBRAppearance {
        baseColor 0 1 0
        metalness 0
      }
      geometry Box {
        size 0.1 0.05 0.1
      }
    }
  ]
  boundingObject USE Body
  physics Physics {
  }
  controller "inz_controller_py"
}
