#VRML_SIM R2021b utf8
WorldInfo {
  coordinateSystem "NUE"
}
Viewpoint {
  orientation -0.04434333657615696 -0.9989786380855569 -0.00868038881730474 1.196793325073661
  position 0.22805248617178842 0.08264082039941144 1.0798076650517687
}
TexturedBackground {
}
TexturedBackgroundLight {
}
DEF GROUND Group {
  children [
    Solid {
      translation 2.1 0 0
      children [
        Shape {
          appearance Appearance {
            texture ImageTexture {
              url [
                "../tiles/RT.png"
              ]
            }
          }
          geometry Plane {
            size 0.3 0.3
          }
        }
      ]
      name "solid7"
    }
    Solid {
      translation 2.1 0 0.3
      children [
        Shape {
          appearance Appearance {
            texture ImageTexture {
              url [
                "../tiles/2R.png"
              ]
            }
          }
          geometry Plane {
            size 0.3 0.3
          }
        }
      ]
      name "solid72"
    }
    Solid {
      translation 2.1 0 0.6
      children [
        Shape {
          appearance Appearance {
            texture ImageTexture {
              url [
                "../tiles/2R.png"
              ]
            }
          }
          geometry Plane {
            size 0.3 0.3
          }
        }
      ]
      name "solid73"
    }
    Solid {
      translation 2.1 0 0.9
      children [
        Shape {
          appearance Appearance {
            texture ImageTexture {
              url [
                "../tiles/2R.png"
              ]
            }
          }
          geometry Plane {
            size 0.3 0.3
          }
        }
      ]
      name "solid74"
    }
    Solid {
      translation 2.1 0 1.2
      children [
        Shape {
          appearance Appearance {
            texture ImageTexture {
              url [
                "../tiles/2R.png"
              ]
            }
          }
          geometry Plane {
            size 0.3 0.3
          }
        }
      ]
      name "solid75"
    }
    Solid {
      translation 2.1 0 1.5
      children [
        Shape {
          appearance Appearance {
            texture ImageTexture {
              url [
                "../tiles/2R.png"
              ]
            }
          }
          geometry Plane {
            size 0.3 0.3
          }
        }
      ]
      name "solid76"
    }
    Solid {
      translation 2.1 0 1.8
      children [
        Shape {
          appearance Appearance {
            texture ImageTexture {
              url [
                "../tiles/RB.png"
              ]
            }
          }
          geometry Plane {
            size 0.3 0.3
          }
        }
      ]
      name "solid77"
    }
    Solid {
      translation 1.8 0 0
      children [
        Shape {
          appearance Appearance {
            texture ImageTexture {
              url [
                "../tiles/1T.png"
              ]
            }
          }
          geometry Plane {
            size 0.3 0.3
          }
        }
      ]
      name "solid6"
    }
    Solid {
      translation 1.8 0 0.3
      children [
        Shape {
          appearance Appearance {
            texture ImageTexture {
              url [
                "../tiles/0.png"
              ]
            }
          }
          geometry Plane {
            size 0.3 0.3
          }
        }
      ]
      name "solid62"
    }
    Solid {
      translation 1.8 0 0.6
      children [
        Shape {
          appearance Appearance {
            texture ImageTexture {
              url [
                "../tiles/0.png"
              ]
            }
          }
          geometry Plane {
            size 0.3 0.3
          }
        }
      ]
      name "solid63"
    }
    Solid {
      translation 1.8 0 0.9
      children [
        Shape {
          appearance Appearance {
            texture ImageTexture {
              url [
                "../tiles/0.png"
              ]
            }
          }
          geometry Plane {
            size 0.3 0.3
          }
        }
      ]
      name "solid64"
    }
    Solid {
      translation 1.8 0 1.2
      children [
        Shape {
          appearance Appearance {
            texture ImageTexture {
              url [
                "../tiles/0.png"
              ]
            }
          }
          geometry Plane {
            size 0.3 0.3
          }
        }
      ]
      name "solid65"
    }
    Solid {
      translation 1.8 0 1.5
      children [
        Shape {
          appearance Appearance {
            texture ImageTexture {
              url [
                "../tiles/0.png"
              ]
            }
          }
          geometry Plane {
            size 0.3 0.3
          }
        }
      ]
      name "solid66"
    }
    Solid {
      translation 1.8 0 1.8
      children [
        Shape {
          appearance Appearance {
            texture ImageTexture {
              url [
                "../tiles/1B.png"
              ]
            }
          }
          geometry Plane {
            size 0.3 0.3
          }
        }
      ]
      name "solid67"
    }
    Solid {
      translation 1.5 0 0
      children [
        Shape {
          appearance Appearance {
            texture ImageTexture {
              url [
                "../tiles/1T.png"
              ]
            }
          }
          geometry Plane {
            size 0.3 0.3
          }
        }
      ]
      name "solid5"
    }
    Solid {
      translation 1.5 0 0.3
      children [
        Shape {
          appearance Appearance {
            texture ImageTexture {
              url [
                "../tiles/0.png"
              ]
            }
          }
          geometry Plane {
            size 0.3 0.3
          }
        }
      ]
      name "solid52"
    }
    Solid {
      translation 1.5 0 0.6
      children [
        Shape {
          appearance Appearance {
            texture ImageTexture {
              url [
                "../tiles/0.png"
              ]
            }
          }
          geometry Plane {
            size 0.3 0.3
          }
        }
      ]
      name "solid53"
    }
    Solid {
      translation 1.5 0 0.9
      children [
        Shape {
          appearance Appearance {
            texture ImageTexture {
              url [
                "../tiles/0.png"
              ]
            }
          }
          geometry Plane {
            size 0.3 0.3
          }
        }
      ]
      name "solid54"
    }
    Solid {
      translation 1.5 0 1.2
      children [
        Shape {
          appearance Appearance {
            texture ImageTexture {
              url [
                "../tiles/0.png"
              ]
            }
          }
          geometry Plane {
            size 0.3 0.3
          }
        }
      ]
      name "solid55"
    }
    Solid {
      translation 1.5 0 1.5
      children [
        Shape {
          appearance Appearance {
            texture ImageTexture {
              url [
                "../tiles/0.png"
              ]
            }
          }
          geometry Plane {
            size 0.3 0.3
          }
        }
      ]
      name "solid56"
    }
    Solid {
      translation 1.5 0 1.8
      children [
        Shape {
          appearance Appearance {
            texture ImageTexture {
              url [
                "../tiles/1B.png"
              ]
            }
          }
          geometry Plane {
            size 0.3 0.3
          }
        }
      ]
      name "solid57"
    }
    Solid {
      translation 1.2 0 0
      children [
        Shape {
          appearance Appearance {
            texture ImageTexture {
              url [
                "../tiles/1T.png"
              ]
            }
          }
          geometry Plane {
            size 0.3 0.3
          }
        }
      ]
      name "solid4"
    }
    Solid {
      translation 1.2 0 0.3
      children [
        Shape {
          appearance Appearance {
            texture ImageTexture {
              url [
                "../tiles/0.png"
              ]
            }
          }
          geometry Plane {
            size 0.3 0.3
          }
        }
      ]
      name "solid42"
    }
    Solid {
      translation 1.2 0 0.6
      children [
        Shape {
          appearance Appearance {
            texture ImageTexture {
              url [
                "../tiles/0.png"
              ]
            }
          }
          geometry Plane {
            size 0.3 0.3
          }
        }
      ]
      name "solid43"
    }
    Solid {
      translation 1.2 0 0.9
      children [
        Shape {
          appearance Appearance {
            texture ImageTexture {
              url [
                "../tiles/20.png"
              ]
            }
          }
          geometry Plane {
            size 0.3 0.3
          }
        }
      ]
      name "solid44"
    }
    Solid {
      translation 1.2 0 1.2
      children [
        Shape {
          appearance Appearance {
            texture ImageTexture {
              url [
                "../tiles/0.png"
              ]
            }
          }
          geometry Plane {
            size 0.3 0.3
          }
        }
      ]
      name "solid45"
    }
    Solid {
      translation 1.2 0 1.5
      children [
        Shape {
          appearance Appearance {
            texture ImageTexture {
              url [
                "../tiles/0.png"
              ]
            }
          }
          geometry Plane {
            size 0.3 0.3
          }
        }
      ]
      name "solid46"
    }
    Solid {
      translation 1.2 0 1.8
      children [
        Shape {
          appearance Appearance {
            texture ImageTexture {
              url [
                "../tiles/1B.png"
              ]
            }
          }
          geometry Plane {
            size 0.3 0.3
          }
        }
      ]
      name "solid47"
    }
    Solid {
      translation 0.9 0 0
      children [
        Shape {
          appearance Appearance {
            texture ImageTexture {
              url [
                "../tiles/1T.png"
              ]
            }
          }
          geometry Plane {
            size 0.3 0.3
          }
        }
      ]
      name "solid3"
    }
    Solid {
      translation 0.9 0 0.3
      children [
        Shape {
          appearance Appearance {
            texture ImageTexture {
              url [
                "../tiles/0.png"
              ]
            }
          }
          geometry Plane {
            size 0.3 0.3
          }
        }
      ]
      name "solid32"
    }
    Solid {
      translation 0.9 0 0.6
      children [
        Shape {
          appearance Appearance {
            texture ImageTexture {
              url [
                "../tiles/0.png"
              ]
            }
          }
          geometry Plane {
            size 0.3 0.3
          }
        }
      ]
      name "solid33"
    }
    Solid {
      translation 0.9 0 0.9
      children [
        Shape {
          appearance Appearance {
            texture ImageTexture {
              url [
                "../tiles/0.png"
              ]
            }
          }
          geometry Plane {
            size 0.3 0.3
          }
        }
      ]
      name "solid34"
    }
    Solid {
      translation 0.9 0 1.2
      children [
        Shape {
          appearance Appearance {
            texture ImageTexture {
              url [
                "../tiles/0.png"
              ]
            }
          }
          geometry Plane {
            size 0.3 0.3
          }
        }
      ]
      name "solid35"
    }
    Solid {
      translation 0.9 0 1.5
      children [
        Shape {
          appearance Appearance {
            texture ImageTexture {
              url [
                "../tiles/0.png"
              ]
            }
          }
          geometry Plane {
            size 0.3 0.3
          }
        }
      ]
      name "solid36"
    }
    Solid {
      translation 0.9 0 1.8
      children [
        Shape {
          appearance Appearance {
            texture ImageTexture {
              url [
                "../tiles/1B.png"
              ]
            }
          }
          geometry Plane {
            size 0.3 0.3
          }
        }
      ]
      name "solid37"
    }
    Solid {
      translation 0.3 0 0
      children [
        Shape {
          appearance Appearance {
            texture ImageTexture {
              url [
                "../tiles/LT.png"
              ]
            }
          }
          geometry Plane {
            size 0.3 0.3
          }
        }
      ]
      name "solid1"
    }
    Solid {
      translation 0.3 0 0.3
      children [
        Shape {
          appearance Appearance {
            texture ImageTexture {
              url [
                "../tiles/2L.png"
              ]
            }
          }
          geometry Plane {
            size 0.3 0.3
          }
        }
      ]
      name "solid12"
    }
    Solid {
      translation 0.3 0 0.6
      children [
        Shape {
          appearance Appearance {
            texture ImageTexture {
              url [
                "../tiles/2L.png"
              ]
            }
          }
          geometry Plane {
            size 0.3 0.3
          }
        }
      ]
      name "solid13"
    }
    Solid {
      translation 0.3 0 0.9
      children [
        Shape {
          appearance Appearance {
            texture ImageTexture {
              url [
                "../tiles/2L.png"
              ]
            }
          }
          geometry Plane {
            size 0.3 0.3
          }
        }
      ]
      name "solid14"
    }
    Solid {
      translation 0.3 0 1.2
      children [
        Shape {
          appearance Appearance {
            texture ImageTexture {
              url [
                "../tiles/2L.png"
              ]
            }
          }
          geometry Plane {
            size 0.3 0.3
          }
        }
      ]
      name "solid15"
    }
    Solid {
      translation 0.3 0 1.5
      children [
        Shape {
          appearance Appearance {
            texture ImageTexture {
              url [
                "../tiles/2L.png"
              ]
            }
          }
          geometry Plane {
            size 0.3 0.3
          }
        }
      ]
      name "solid16"
    }
    Solid {
      translation 0.3 0 1.8
      children [
        Shape {
          appearance Appearance {
            texture ImageTexture {
              url [
                "../tiles/LB.png"
              ]
            }
          }
          geometry Plane {
            size 0.3 0.3
          }
        }
      ]
      name "solid17"
    }
    Solid {
      translation 0.6 0 0
      children [
        Shape {
          appearance Appearance {
            texture ImageTexture {
              url [
                "../tiles/1T.png"
              ]
            }
          }
          geometry Plane {
            size 0.3 0.3
          }
        }
      ]
      name "solid2"
    }
    Solid {
      translation 0.6 0 0.3
      children [
        Shape {
          appearance Appearance {
            texture ImageTexture {
              url [
                "../tiles/0.png"
              ]
            }
          }
          geometry Plane {
            size 0.3 0.3
          }
        }
      ]
      name "solid22"
    }
    Solid {
      translation 0.6 0 0.6
      children [
        Shape {
          appearance Appearance {
            texture ImageTexture {
              url [
                "../tiles/0.png"
              ]
            }
          }
          geometry Plane {
            size 0.3 0.3
          }
        }
      ]
      name "solid23"
    }
    Solid {
      translation 0.6 0 0.9
      children [
        Shape {
          appearance Appearance {
            texture ImageTexture {
              url [
                "../tiles/10.png"
              ]
            }
          }
          geometry Plane {
            size 0.3 0.3
          }
        }
      ]
      name "solid24"
    }
    Solid {
      translation 0.6 0 1.2
      children [
        Shape {
          appearance Appearance {
            texture ImageTexture {
              url [
                "../tiles/0.png"
              ]
            }
          }
          geometry Plane {
            size 0.3 0.3
          }
        }
      ]
      name "solid25"
    }
    Solid {
      translation 0.6 0 1.5
      children [
        Shape {
          appearance Appearance {
            texture ImageTexture {
              url [
                "../tiles/0.png"
              ]
            }
          }
          geometry Plane {
            size 0.3 0.3
          }
        }
      ]
      name "solid26"
    }
    Solid {
      translation 0.6 0 1.8
      children [
        Shape {
          appearance Appearance {
            texture ImageTexture {
              url [
                "../tiles/1B.png"
              ]
            }
          }
          geometry Plane {
            size 0.3 0.3
          }
        }
      ]
      name "solid27"
    }
    Solid {
      translation 1.25 -0.049 1
      boundingObject Box {
        size 2.5 0.1 2.5
      }
    }
  ]
}
DEF LIGHTSOURCE Group {
  children [
    PointLight {
      attenuation 0 0 1
      color 0 0 1
      intensity 0.25
      location 1.1 0.25 0.9
    }
  ]
}
DEF WALLS Group {
  children [
    Wall {
      translation 1.2 0 0.75
      name "wall1"
      size 0.3 0.5 0.05
    }
    Wall {
      translation 1.2 0 1.05
      name "wall2"
      size 0.3 0.5 0.05
    }
    Wall {
      translation 1.05 0 0.9
      name "wall3"
      size 0.05 0.5 0.3
    }
    Wall {
      translation 0.75 0 0
      name "wall4"
      size 0.05 0.5 0.3
    }
    Wall {
      translation 1.65 0 1.8
      name "wall7"
      size 0.05 0.5 0.3
    }
    Wall {
      translation 1.65 0 0
      name "wall6"
      size 0.05 0.5 0.3
    }
    Wall {
      translation 0.75 0 1.8
      name "wall5"
      size 0.05 0.5 0.3
    }
    Wall {
      translation 1.65 0 0.6
      name "wall8"
      size 0.05 0.5 0.3
    }
    Wall {
      translation 1.65 0 1.2
      name "wall9"
      size 0.05 0.5 0.3
    }
    Wall {
      translation 2.1 0 0.75
      name "wall10"
      size 0.3 0.5 0.05
    }
    Wall {
      translation 1.8 0 1.05
      name "wall11"
      size 0.3 0.5 0.05
    }
    Wall {
      translation 1.5 0 0.75
      name "wall12"
      size 0.3 0.5 0.05
    }
    Wall {
      translation 1.05 0 1.2
      name "wall13"
      size 0.05 0.5 0.3
    }
    Wall {
      translation 1.5 0 1.35
      name "wall14"
      size 0.3 0.5 0.05
    }
    Wall {
      translation 0.9 0 0.45
      name "wall15"
      size 0.3 0.5 0.05
    }
    Wall {
      translation 0.9 0 0.15
      name "wall16"
      size 0.3 0.5 0.05
    }
    Wall {
      translation 1.2 0 0.15
      name "wall17"
      size 0.3 0.5 0.05
    }
    Wall {
      translation 0.3 0 0.45
      name "wall18"
      size 0.3 0.5 0.05
    }
    Wall {
      translation 0.3 0 1.35
      name "wall19"
      size 0.3 0.5 0.05
    }
    Wall {
      translation 0.6 0 1.35
      name "wall20"
      size 0.3 0.5 0.05
    }
  ]
}
Robot {
  translation 0.6059297241044342 0.040904462095366606 0.8833772926780908
  rotation 3.8578100340012506e-05 0.9999990311283857 0.001391493449430153 0.27439019875927995
  children [
    LightSensor {
      translation 0 -0.02 0.05
      rotation 0 0 1 -1.5707996938995747
      children [
        Shape {
          appearance PBRAppearance {
          }
          geometry Box {
            size 0.01 0.02 0.01
          }
        }
      ]
      name "line_detector_sensor"
    }
    LightSensor {
      translation 0 0.02 0.05
      rotation 0 1 0 -1.59
      children [
        Shape {
          appearance PBRAppearance {
          }
          geometry Box {
            size 0.01 0.01 0.01
          }
        }
      ]
      name "light_sensor"
    }
    HingeJoint {
      jointParameters HingeJointParameters {
        position 1.0000000007351713
        anchor -0.02 -0.02 0.03
      }
      device [
        RotationalMotor {
          name "FLWHEEL"
        }
      ]
      endPoint Solid {
        translation -0.049999999999999996 -0.02 0.03
        rotation 0.32538483345550573 -0.33169419279944923 -0.8854962860567256 4.572040153219656
        children [
          Shape {
            appearance PBRAppearance {
            }
            geometry Cylinder {
              height 0.02
              radius 0.02
            }
          }
        ]
        boundingObject Cylinder {
          height 0.02
          radius 0.02
        }
        physics Physics {
        }
        linearVelocity -1.8177412553492384e-09 2.1588064163691614e-08 -1.0927890226923189e-08
        angularVelocity -9.435880753360923e-07 -6.237339681333891e-09 1.8581604599886626e-07
      }
    }
    HingeJoint {
      jointParameters HingeJointParameters {
        position 15.000000126124366
        anchor -0.02 -0.02 -0.03
      }
      device [
        RotationalMotor {
          name "BLWHEEL"
        }
      ]
      endPoint Solid {
        translation -0.05000000000000003 -0.02 -0.03
        rotation 0.5417282101898491 -0.5522325656281202 0.6336953051303811 2.0292316665044248
        children [
          Shape {
            appearance PBRAppearance {
            }
            geometry Cylinder {
              height 0.02
              radius 0.02
            }
          }
        ]
        name "solid(2)"
        boundingObject Cylinder {
          height 0.02
          radius 0.02
        }
        physics Physics {
        }
        linearVelocity 3.373032450587574e-09 1.661269194215339e-08 6.625503377615248e-09
        angularVelocity 5.440931887110027e-07 -5.016963378733912e-09 -2.327267133463815e-07
      }
    }
    HingeJoint {
      jointParameters HingeJointParameters {
        position 8.999999998877271
        anchor 0.015 -0.02 -0.03
      }
      device [
        RotationalMotor {
          name "BRWHEEL"
        }
      ]
      endPoint Solid {
        translation 0.04999999999999998 -0.02 -0.03
        rotation -0.6921320418893862 0.7055527957682999 -0.1521462749250362 3.4379097128183274
        children [
          Shape {
            appearance PBRAppearance {
            }
            geometry Cylinder {
              height 0.02
              radius 0.02
            }
          }
        ]
        name "solid(3)"
        boundingObject Cylinder {
          height 0.02
          radius 0.02
        }
        physics Physics {
        }
        linearVelocity -1.3513837663473528e-09 1.0303150255177567e-08 -1.1534929220211014e-08
        angularVelocity -9.901085845505823e-07 -5.468665213226135e-09 2.0040858040937639e-07
      }
    }
    HingeJoint {
      jointParameters HingeJointParameters {
        position 5.081613452108671e-11
        anchor 0.015 -0.02 0.03
      }
      device [
        RotationalMotor {
          name "FRWHEEL"
        }
      ]
      endPoint Solid {
        translation 0.05 -0.02 0.03
        rotation -0.677119379679315 0.6902490312361357 0.25507963568320335 2.6512069098654414
        children [
          Shape {
            appearance PBRAppearance {
            }
            geometry Cylinder {
              height 0.02
              radius 0.02
            }
          }
        ]
        name "solid(1)"
        boundingObject Cylinder {
          height 0.02
          radius 0.02
        }
        physics Physics {
        }
        linearVelocity 3.676339101896069e-09 1.0592387353466413e-08 6.73975060730954e-09
        angularVelocity 7.343185404057752e-07 -5.636201619542631e-09 -2.8510307507539283e-07
      }
    }
    DistanceSensor {
      translation -847.3809512687511 -2238889.580312604 -93.09121555418194
      rotation 0.01112216575729272 -0.9999129210601427 -0.007102656252445453 1.5776432937483473
      children [
        Shape {
          appearance PBRAppearance {
          }
          geometry Box {
            size 0.01 0.01 0.02
          }
        }
      ]
      name "distance_sensor"
      physics Physics {
      }
      linearVelocity 0 -6601.737599997389 0
    }
    DEF Body Shape {
      appearance PBRAppearance {
        baseColor 0 1 0
        metalness 0
      }
      geometry Box {
        size 0.1 0.05 0.1
      }
    }
  ]
  boundingObject USE Body
  physics Physics {
  }
  controller "inz_controller"
}
Robot {
  translation 0.5794289274236076 0.025873523751253107 0.7420615124919897
  rotation 0.033958666932472445 0.9985735646609705 0.041202486580934714 0.16504980698238403
  children [
    MindstormsRover {
      hidden position_0_0 314.96948446394885
      hidden position_0_1 1574.847915056471
      hidden translation_2 -0.00906332194306525 0.01600962071776846 -0.03647912273638021
      hidden rotation_2 -0.011572736069418199 -0.9999002184978273 0.008100915248592739 2.997948740161699e-15
      hidden linearVelocity_2 7.211162834634626e-16 -1.7824630660356888e-13 2.279195111410772e-14
      hidden angularVelocity_2 1.460335586226252e-12 7.998665690477336e-15 -3.377231881040407e-14
      hidden translation_3 -0.057063321956136004 0.016009620717760208 -0.03647912273716336
      hidden rotation_3 -0.006943848559144068 -0.999871245536725 0.014466351164883474 2.9978594052586378e-15
      hidden linearVelocity_3 7.069526890249319e-16 -1.4366285938649526e-13 2.23430578621195e-14
      hidden angularVelocity_3 1.4608644730094961e-12 7.989240824416659e-15 -3.371449052699367e-14
      hidden translation_4 -0.022742999999999954 0.011918 0
      hidden rotation_4 0.9999999999999999 0 0 3.7792108958364565
      hidden linearVelocity_4 6.123996919802111e-16 -1.1372252120424496e-13 1.6676854200320104e-14
      hidden angularVelocity_4 0.17090134102749774 0.0003733366461492682 -0.10388740181200777
      hidden translation_5 0.02251299999999998 0.011918 0
      hidden rotation_5 -1 0 0 3.1713993914902874
      hidden linearVelocity_5 6.09055654617065e-16 -1.4658496264792902e-13 1.644369132848073e-14
      hidden angularVelocity_5 0.8545067068042322 0.0018667182880864953 -0.519437006182574
      translation -0.2717500173047599 -0.024309445432263304 0.10303899149749396
      rotation 0.001462234138059575 0.9999442218255041 -0.010460167738254544 -2.7601747241151404
    }
  ]
  name "updated"
  boundingObject USE Body
  physics Physics {
  }
  linearVelocity 6.062507636134074e-16 3.439026841078885e-14 3.611088375898917e-14
  angularVelocity 1.4562262852258745e-12 7.635043110093425e-15 -3.0768129667181225e-14
}
