#VRML_SIM R2021b utf8
WorldInfo {
  coordinateSystem "NUE"
}
Viewpoint {
  orientation -0.6224627932532298 -0.7326272902190392 -0.2753131392463763 0.9320001701125858
  position -0.5248418896794587 1.3247318360974916 2.424508113047104
  follow "robot:distance_sensor_front"
  followType "None"
}
TexturedBackground {
}
TexturedBackgroundLight {
}
DEF GROUND Group {
  children [
    Solid {
      translation 2.1 0 0
      children [
        Shape {
          appearance Appearance {
            texture ImageTexture {
              url [
                "../tiles/RT.png"
              ]
            }
          }
          geometry Plane {
            size 0.3 0.3
          }
        }
      ]
      name "solid7"
    }
    Solid {
      translation 2.1 0 0.3
      children [
        Shape {
          appearance Appearance {
            texture ImageTexture {
              url [
                "../tiles/2R.png"
              ]
            }
          }
          geometry Plane {
            size 0.3 0.3
          }
        }
      ]
      name "solid72"
    }
    Solid {
      translation 2.1 0 0.6
      children [
        Shape {
          appearance Appearance {
            texture ImageTexture {
              url [
                "../tiles/2R.png"
              ]
            }
          }
          geometry Plane {
            size 0.3 0.3
          }
        }
      ]
      name "solid73"
    }
    Solid {
      translation 2.1 0 0.9
      children [
        Shape {
          appearance Appearance {
            texture ImageTexture {
              url [
                "../tiles/2R.png"
              ]
            }
          }
          geometry Plane {
            size 0.3 0.3
          }
        }
      ]
      name "solid74"
    }
    Solid {
      translation 2.1 0 1.2
      children [
        Shape {
          appearance Appearance {
            texture ImageTexture {
              url [
                "../tiles/2R.png"
              ]
            }
          }
          geometry Plane {
            size 0.3 0.3
          }
        }
      ]
      name "solid75"
    }
    Solid {
      translation 2.1 0 1.5
      children [
        Shape {
          appearance Appearance {
            texture ImageTexture {
              url [
                "../tiles/2R.png"
              ]
            }
          }
          geometry Plane {
            size 0.3 0.3
          }
        }
      ]
      name "solid76"
    }
    Solid {
      translation 2.1 0 1.8
      children [
        Shape {
          appearance Appearance {
            texture ImageTexture {
              url [
                "../tiles/RB.png"
              ]
            }
          }
          geometry Plane {
            size 0.3 0.3
          }
        }
      ]
      name "solid77"
    }
    Solid {
      translation 1.8 0 0
      children [
        Shape {
          appearance Appearance {
            texture ImageTexture {
              url [
                "../tiles/1T.png"
              ]
            }
          }
          geometry Plane {
            size 0.3 0.3
          }
        }
      ]
      name "solid6"
    }
    Solid {
      translation 1.8 0 0.3
      children [
        Shape {
          appearance Appearance {
            texture ImageTexture {
              url [
                "../tiles/0.png"
              ]
            }
          }
          geometry Plane {
            size 0.3 0.3
          }
        }
      ]
      name "solid62"
    }
    Solid {
      translation 1.8 0 0.6
      children [
        Shape {
          appearance Appearance {
            texture ImageTexture {
              url [
                "../tiles/0.png"
              ]
            }
          }
          geometry Plane {
            size 0.3 0.3
          }
        }
      ]
      name "solid63"
    }
    Solid {
      translation 1.8 0 0.9
      children [
        Shape {
          appearance Appearance {
            texture ImageTexture {
              url [
                "../tiles/0.png"
              ]
            }
          }
          geometry Plane {
            size 0.3 0.3
          }
        }
      ]
      name "solid64"
    }
    Solid {
      translation 1.8 0 1.2
      children [
        Shape {
          appearance Appearance {
            texture ImageTexture {
              url [
                "../tiles/0.png"
              ]
            }
          }
          geometry Plane {
            size 0.3 0.3
          }
        }
      ]
      name "solid65"
    }
    Solid {
      translation 1.8 0 1.5
      children [
        Shape {
          appearance Appearance {
            texture ImageTexture {
              url [
                "../tiles/0.png"
              ]
            }
          }
          geometry Plane {
            size 0.3 0.3
          }
        }
      ]
      name "solid66"
    }
    Solid {
      translation 1.8 0 1.8
      children [
        Shape {
          appearance Appearance {
            texture ImageTexture {
              url [
                "../tiles/1B.png"
              ]
            }
          }
          geometry Plane {
            size 0.3 0.3
          }
        }
      ]
      name "solid67"
    }
    Solid {
      translation 1.5 0 0
      children [
        Shape {
          appearance Appearance {
            texture ImageTexture {
              url [
                "../tiles/1T.png"
              ]
            }
          }
          geometry Plane {
            size 0.3 0.3
          }
        }
      ]
      name "solid5"
    }
    Solid {
      translation 1.5 0 0.3
      children [
        Shape {
          appearance Appearance {
            texture ImageTexture {
              url [
                "../tiles/0.png"
              ]
            }
          }
          geometry Plane {
            size 0.3 0.3
          }
        }
      ]
      name "solid52"
    }
    Solid {
      translation 1.5 0 0.6
      children [
        Shape {
          appearance Appearance {
            texture ImageTexture {
              url [
                "../tiles/0.png"
              ]
            }
          }
          geometry Plane {
            size 0.3 0.3
          }
        }
      ]
      name "solid53"
    }
    Solid {
      translation 1.5 0 0.9
      children [
        Shape {
          appearance Appearance {
            texture ImageTexture {
              url [
                "../tiles/0.png"
              ]
            }
          }
          geometry Plane {
            size 0.3 0.3
          }
        }
      ]
      name "solid54"
    }
    Solid {
      translation 1.5 0 1.2
      children [
        Shape {
          appearance Appearance {
            texture ImageTexture {
              url [
                "../tiles/0.png"
              ]
            }
          }
          geometry Plane {
            size 0.3 0.3
          }
        }
      ]
      name "solid55"
    }
    Solid {
      translation 1.5 0 1.5
      children [
        Shape {
          appearance Appearance {
            texture ImageTexture {
              url [
                "../tiles/0.png"
              ]
            }
          }
          geometry Plane {
            size 0.3 0.3
          }
        }
      ]
      name "solid56"
    }
    Solid {
      translation 1.5 0 1.8
      children [
        Shape {
          appearance Appearance {
            texture ImageTexture {
              url [
                "../tiles/1B.png"
              ]
            }
          }
          geometry Plane {
            size 0.3 0.3
          }
        }
      ]
      name "solid57"
    }
    Solid {
      translation 1.2 0 0
      children [
        Shape {
          appearance Appearance {
            texture ImageTexture {
              url [
                "../tiles/1T.png"
              ]
            }
          }
          geometry Plane {
            size 0.3 0.3
          }
        }
      ]
      name "solid4"
    }
    Solid {
      translation 1.2 0 0.3
      children [
        Shape {
          appearance Appearance {
            texture ImageTexture {
              url [
                "../tiles/0.png"
              ]
            }
          }
          geometry Plane {
            size 0.3 0.3
          }
        }
      ]
      name "solid42"
    }
    Solid {
      translation 1.2 0 0.6
      children [
        Shape {
          appearance Appearance {
            texture ImageTexture {
              url [
                "../tiles/0.png"
              ]
            }
          }
          geometry Plane {
            size 0.3 0.3
          }
        }
      ]
      name "solid43"
    }
    Solid {
      translation 1.2 0 0.9
      children [
        Shape {
          appearance Appearance {
            texture ImageTexture {
              url [
                "../tiles/20.png"
              ]
            }
          }
          geometry Plane {
            size 0.3 0.3
          }
        }
      ]
      name "solid44"
    }
    Solid {
      translation 1.2 0 1.2
      children [
        Shape {
          appearance Appearance {
            texture ImageTexture {
              url [
                "../tiles/0.png"
              ]
            }
          }
          geometry Plane {
            size 0.3 0.3
          }
        }
      ]
      name "solid45"
    }
    Solid {
      translation 1.2 0 1.5
      children [
        Shape {
          appearance Appearance {
            texture ImageTexture {
              url [
                "../tiles/0.png"
              ]
            }
          }
          geometry Plane {
            size 0.3 0.3
          }
        }
      ]
      name "solid46"
    }
    Solid {
      translation 1.2 0 1.8
      children [
        Shape {
          appearance Appearance {
            texture ImageTexture {
              url [
                "../tiles/1B.png"
              ]
            }
          }
          geometry Plane {
            size 0.3 0.3
          }
        }
      ]
      name "solid47"
    }
    Solid {
      translation 0.9 0 0
      children [
        Shape {
          appearance Appearance {
            texture ImageTexture {
              url [
                "../tiles/1T.png"
              ]
            }
          }
          geometry Plane {
            size 0.3 0.3
          }
        }
      ]
      name "solid3"
    }
    Solid {
      translation 0.9 0 0.3
      children [
        Shape {
          appearance Appearance {
            texture ImageTexture {
              url [
                "../tiles/0.png"
              ]
            }
          }
          geometry Plane {
            size 0.3 0.3
          }
        }
      ]
      name "solid32"
    }
    Solid {
      translation 0.9 0 0.6
      children [
        Shape {
          appearance Appearance {
            texture ImageTexture {
              url [
                "../tiles/0.png"
              ]
            }
          }
          geometry Plane {
            size 0.3 0.3
          }
        }
      ]
      name "solid33"
    }
    Solid {
      translation 0.9 0 0.9
      children [
        Shape {
          appearance Appearance {
            texture ImageTexture {
              url [
                "../tiles/0.png"
              ]
            }
          }
          geometry Plane {
            size 0.3 0.3
          }
        }
      ]
      name "solid34"
    }
    Solid {
      translation 0.9 0 1.2
      children [
        Shape {
          appearance Appearance {
            texture ImageTexture {
              url [
                "../tiles/0.png"
              ]
            }
          }
          geometry Plane {
            size 0.3 0.3
          }
        }
      ]
      name "solid35"
    }
    Solid {
      translation 0.9 0 1.5
      children [
        Shape {
          appearance Appearance {
            texture ImageTexture {
              url [
                "../tiles/0.png"
              ]
            }
          }
          geometry Plane {
            size 0.3 0.3
          }
        }
      ]
      name "solid36"
    }
    Solid {
      translation 0.9 0 1.8
      children [
        Shape {
          appearance Appearance {
            texture ImageTexture {
              url [
                "../tiles/1B.png"
              ]
            }
          }
          geometry Plane {
            size 0.3 0.3
          }
        }
      ]
      name "solid37"
    }
    Solid {
      translation 0.3 0 0
      children [
        Shape {
          appearance Appearance {
            texture ImageTexture {
              url [
                "../tiles/LT.png"
              ]
            }
          }
          geometry Plane {
            size 0.3 0.3
          }
        }
      ]
      name "solid1"
    }
    Solid {
      translation 0.3 0 0.3
      children [
        Shape {
          appearance Appearance {
            texture ImageTexture {
              url [
                "../tiles/2L.png"
              ]
            }
          }
          geometry Plane {
            size 0.3 0.3
          }
        }
      ]
      name "solid12"
    }
    Solid {
      translation 0.3 0 0.6
      children [
        Shape {
          appearance Appearance {
            texture ImageTexture {
              url [
                "../tiles/2L.png"
              ]
            }
          }
          geometry Plane {
            size 0.3 0.3
          }
        }
      ]
      name "solid13"
    }
    Solid {
      translation 0.3 0 0.9
      children [
        Shape {
          appearance Appearance {
            texture ImageTexture {
              url [
                "../tiles/2L.png"
              ]
            }
          }
          geometry Plane {
            size 0.3 0.3
          }
        }
      ]
      name "solid14"
    }
    Solid {
      translation 0.3 0 1.2
      children [
        Shape {
          appearance Appearance {
            texture ImageTexture {
              url [
                "../tiles/2L.png"
              ]
            }
          }
          geometry Plane {
            size 0.3 0.3
          }
        }
      ]
      name "solid15"
    }
    Solid {
      translation 0.3 0 1.5
      children [
        Shape {
          appearance Appearance {
            texture ImageTexture {
              url [
                "../tiles/2L.png"
              ]
            }
          }
          geometry Plane {
            size 0.3 0.3
          }
        }
      ]
      name "solid16"
    }
    Solid {
      translation 0.3 0 1.8
      children [
        Shape {
          appearance Appearance {
            texture ImageTexture {
              url [
                "../tiles/LB.png"
              ]
            }
          }
          geometry Plane {
            size 0.3 0.3
          }
        }
      ]
      name "solid17"
    }
    Solid {
      translation 0.6 0 0
      children [
        Shape {
          appearance Appearance {
            texture ImageTexture {
              url [
                "../tiles/1T.png"
              ]
            }
          }
          geometry Plane {
            size 0.3 0.3
          }
        }
      ]
      name "solid2"
    }
    Solid {
      translation 0.6 0 0.3
      children [
        Shape {
          appearance Appearance {
            texture ImageTexture {
              url [
                "../tiles/0.png"
              ]
            }
          }
          geometry Plane {
            size 0.3 0.3
          }
        }
      ]
      name "solid22"
    }
    Solid {
      translation 0.6 0 0.6
      children [
        Shape {
          appearance Appearance {
            texture ImageTexture {
              url [
                "../tiles/0.png"
              ]
            }
          }
          geometry Plane {
            size 0.3 0.3
          }
        }
      ]
      name "solid23"
    }
    Solid {
      translation 0.6 0 0.9
      children [
        Shape {
          appearance Appearance {
            texture ImageTexture {
              url [
                "../tiles/10.png"
              ]
            }
          }
          geometry Plane {
            size 0.3 0.3
          }
        }
      ]
      name "solid24"
    }
    Solid {
      translation 0.6 0 1.2
      children [
        Shape {
          appearance Appearance {
            texture ImageTexture {
              url [
                "../tiles/0.png"
              ]
            }
          }
          geometry Plane {
            size 0.3 0.3
          }
        }
      ]
      name "solid25"
    }
    Solid {
      translation 0.6 0 1.5
      children [
        Shape {
          appearance Appearance {
            texture ImageTexture {
              url [
                "../tiles/0.png"
              ]
            }
          }
          geometry Plane {
            size 0.3 0.3
          }
        }
      ]
      name "solid26"
    }
    Solid {
      translation 0.6 0 1.8
      children [
        Shape {
          appearance Appearance {
            texture ImageTexture {
              url [
                "../tiles/1B.png"
              ]
            }
          }
          geometry Plane {
            size 0.3 0.3
          }
        }
      ]
      name "solid27"
    }
    Solid {
      translation 1.25 -0.049 1
      boundingObject Box {
        size 2.5 0.1 2.5
      }
    }
  ]
}
DEF LIGHTSOURCE Group {
  children [
    PointLight {
      attenuation 0 0 1
      color 0 0 1
      intensity 0.1
      location 1.1 0.1 0.9
    }
  ]
}
DEF WALLS Group {
  children [
    Wall {
      translation 1.2 0 0.75
      name "wall1"
      size 0.3 0.5 0.05
    }
    Wall {
      translation 1.2 0 1.05
      name "wall2"
      size 0.3 0.5 0.05
    }
    Wall {
      translation 1.05 0 0.9
      name "wall3"
      size 0.05 0.5 0.3
    }
    Wall {
      translation 0.75 0 0
      name "wall4"
      size 0.05 0.5 0.3
    }
    Wall {
      translation 1.65 0 1.8
      name "wall7"
      size 0.05 0.5 0.3
    }
    Wall {
      translation 1.65 0 0
      name "wall6"
      size 0.05 0.5 0.3
    }
    Wall {
      translation 0.75 0 1.8
      name "wall5"
      size 0.05 0.5 0.3
    }
    Wall {
      translation 1.65 0 0.6
      name "wall8"
      size 0.05 0.5 0.3
    }
    Wall {
      translation 1.65 0 1.2
      name "wall9"
      size 0.05 0.5 0.3
    }
    Wall {
      translation 2.1 0 0.75
      name "wall10"
      size 0.3 0.5 0.05
    }
    Wall {
      translation 1.8 0 1.05
      name "wall11"
      size 0.3 0.5 0.05
    }
    Wall {
      translation 1.5 0 0.75
      name "wall12"
      size 0.3 0.5 0.05
    }
    Wall {
      translation 1.05 0 1.2
      name "wall13"
      size 0.05 0.5 0.3
    }
    Wall {
      translation 1.5 0 1.35
      name "wall14"
      size 0.3 0.5 0.05
    }
    Wall {
      translation 0.9 0 0.45
      name "wall15"
      size 0.3 0.5 0.05
    }
    Wall {
      translation 0.9 0 0.15
      name "wall16"
      size 0.3 0.5 0.05
    }
    Wall {
      translation 1.2 0 0.15
      name "wall17"
      size 0.3 0.5 0.05
    }
    Wall {
      translation 0.3 0 0.45
      name "wall18"
      size 0.3 0.5 0.05
    }
    Wall {
      translation 0.3 0 1.35
      name "wall19"
      size 0.3 0.5 0.05
    }
    Wall {
      translation 0.6 0 1.35
      name "wall20"
      size 0.3 0.5 0.05
    }
  ]
}
Robot {
  translation 0.6306660133046872 0.05053745304512311 0.4659344864541031
  rotation -5.4723791513885634e-05 0.9999887233385186 -0.004748705203147195 -3.1387091316252964
  scale 1.26961 1.26961 1.26961
  children [
    InertialUnit {
      name "intertialUnit"
    }
    GPS {
    }
    Compass {
    }
    DistanceSensor {
      translation 0 -0.03 0.055
      rotation 0 0 1 -1.5707953071795862
      children [
        Shape {
          appearance PBRAppearance {
          }
          geometry Box {
            size 0.01 0.01 0.01
          }
        }
      ]
      name "line_sensor"
      physics Physics {
      }
      type "infra-red"
    }
    LightSensor {
      translation 0 0.02 0.05
      rotation 0 1 0 -1.59
      children [
        Shape {
          appearance PBRAppearance {
          }
          geometry Box {
            size 0.01 0.01 0.01
          }
        }
      ]
      name "light_sensor"
      colorFilter 0 0 1
      occlusion TRUE
    }
    HingeJoint {
      jointParameters HingeJointParameters {
        position 21708.15198840286
        anchor -0.02 -0.02 0.03
      }
      device [
        RotationalMotor {
          name "FRWHEEL"
        }
      ]
      endPoint Solid {
        translation -0.04999999999999847 -0.02 0.03
        rotation 0.6709288407969661 -0.6709313052607319 0.31576205314757133 2.5298868886473564
        children [
          Shape {
            appearance PBRAppearance {
            }
            geometry Cylinder {
              height 0.02
              radius 0.02
            }
          }
        ]
        boundingObject Cylinder {
          height 0.02
          radius 0.02
        }
        physics Physics {
        }
        linearVelocity -7.322782747294205e-05 1.4349212920286838e-08 -0.025392079492984485
        angularVelocity -0.9999952732063723 -9.692931880704423e-05 0.0028840785310020353
      }
    }
    HingeJoint {
      jointParameters HingeJointParameters {
        position 21722.14316383043
        anchor -0.02 -0.02 -0.03
      }
      device [
        RotationalMotor {
          name "BRWHEEL"
        }
      ]
      endPoint Solid {
        translation -0.050000000000000655 -0.02 -0.03
        rotation 0.670156879709596 -0.6701593413377853 0.31902384518340327 2.5239603561935913
        children [
          Shape {
            appearance PBRAppearance {
            }
            geometry Cylinder {
              height 0.02
              radius 0.02
            }
          }
        ]
        name "solid(2)"
        boundingObject Cylinder {
          height 0.02
          radius 0.02
        }
        physics Physics {
        }
        linearVelocity -7.322850305266796e-05 -2.76999892119316e-08 -0.0253920795025718
        angularVelocity -0.9999952735012198 -9.640245919639414e-05 0.002883994318629855
      }
    }
    HingeJoint {
      jointParameters HingeJointParameters {
        position 31956.63755850513
        anchor 0.015 -0.02 -0.03
      }
      device [
        RotationalMotor {
          name "BLWHEEL"
        }
      ]
      endPoint Solid {
        translation 0.049999999999999226 -0.02 -0.03
        rotation 0.47926798527168657 -0.4792697457245284 0.7352569000878293 1.8735990350806737
        children [
          Shape {
            appearance PBRAppearance {
            }
            geometry Cylinder {
              height 0.02
              radius 0.02
            }
          }
        ]
        name "solid(3)"
        boundingObject Cylinder {
          height 0.02
          radius 0.02
        }
        physics Physics {
        }
        linearVelocity -7.322850278410023e-05 -1.4343780213672695e-08 -0.02539208071850504
        angularVelocity -0.9999952743043485 -9.507066467376851e-05 0.0028837813913542504
      }
    }
    HingeJoint {
      jointParameters HingeJointParameters {
        position 31947.627035457564
        anchor 0.015 -0.02 0.03
      }
      device [
        RotationalMotor {
          name "FLWHEEL"
        }
      ]
      endPoint Solid {
        translation 0.04999999999999951 -0.02 0.03
        rotation 0.47627708579369504 -0.47627883526032844 0.7391336879285981 1.8685755259569674
        children [
          Shape {
            appearance PBRAppearance {
            }
            geometry Cylinder {
              height 0.02
              radius 0.02
            }
          }
        ]
        name "solid(1)"
        boundingObject Cylinder {
          height 0.02
          radius 0.02
        }
        physics Physics {
        }
        linearVelocity -7.322783792773228e-05 2.7709250248169083e-08 -0.0253920807309485
        angularVelocity -0.9999952746460696 -9.445609489415004e-05 0.002883683043960175
      }
    }
    DistanceSensor {
      translation 6.99334e-05 0.00982561 0.0493899
      rotation 0.01112216575729272 -0.9999129210601427 -0.007102656252445453 1.5776432937483473
      children [
        Shape {
          appearance PBRAppearance {
          }
          geometry Box {
            size 0.01 0.01 0.02
          }
        }
      ]
      name "distance_sensor_front"
      physics Physics {
      }
    }
    DistanceSensor {
      translation 0.05 0.0109391 -0.000260794
      rotation 0 -1 0 -5.307179586466759e-06
      children [
        Shape {
          appearance PBRAppearance {
          }
          geometry Box {
            size 0.01 0.01 0.02
          }
        }
      ]
      name "distance_sensor_left"
      physics Physics {
      }
    }
    DistanceSensor {
      translation 0.000742173 0.0116556 -0.0505911
      rotation 0 1 0 1.5708
      children [
        Shape {
          appearance PBRAppearance {
          }
          geometry Box {
            size 0.01 0.01 0.02
          }
        }
      ]
      name "distance_sensor_back"
      physics Physics {
      }
    }
    DistanceSensor {
      translation -0.0492576 0.0116556 -0.0005911
      rotation 0 1 0 -3.1415853071795863
      children [
        Shape {
          appearance PBRAppearance {
          }
          geometry Box {
            size 0.01 0.01 0.02
          }
        }
      ]
      name "distance_sensor_right"
      physics Physics {
      }
    }
    DEF Body Shape {
      appearance PBRAppearance {
        baseColor 0 1 0
        metalness 0
      }
      geometry Box {
        size 0.1 0.05 0.1
      }
    }
  ]
  boundingObject USE Body
  physics Physics {
  }
  controller "inz_controller_py"
  linearVelocity -7.322465766414371e-05 6.4750289683114074e-09 -0.025392064224310062
  angularVelocity 5.627902260780516e-07 -3.7812784443828324e-08 -1.0894865199186642e-07
}
